[2024-05-27T08:20:54.395+0000] {local_task_job_runner.py:120} INFO - ::group::Pre task execution logs
[2024-05-27T08:20:54.421+0000] {taskinstance.py:2073} INFO - Dependencies all met for dep_context=non-requeueable deps ti=<TaskInstance: fetch_parse_store_report_weather_data.fetch_and_save_weather_data scheduled__2024-05-23T11:00:00+00:00 [queued]>
[2024-05-27T08:20:54.433+0000] {taskinstance.py:2073} INFO - Dependencies all met for dep_context=requeueable deps ti=<TaskInstance: fetch_parse_store_report_weather_data.fetch_and_save_weather_data scheduled__2024-05-23T11:00:00+00:00 [queued]>
[2024-05-27T08:20:54.434+0000] {taskinstance.py:2303} INFO - Starting attempt 1 of 2
[2024-05-27T08:20:54.448+0000] {taskinstance.py:2327} INFO - Executing <Task(PythonOperator): fetch_and_save_weather_data> on 2024-05-23 11:00:00+00:00
[2024-05-27T08:20:54.464+0000] {warnings.py:110} WARNING - /home/***/.local/lib/python3.12/site-packages/***/task/task_runner/standard_task_runner.py:61: DeprecationWarning: This process (pid=19976) is multi-threaded, use of fork() may lead to deadlocks in the child.
  pid = os.fork()

[2024-05-27T08:20:54.466+0000] {standard_task_runner.py:63} INFO - Started process 20095 to run task
[2024-05-27T08:20:54.466+0000] {standard_task_runner.py:90} INFO - Running: ['***', 'tasks', 'run', 'fetch_parse_store_report_weather_data', 'fetch_and_save_weather_data', 'scheduled__2024-05-23T11:00:00+00:00', '--job-id', '12127', '--raw', '--subdir', 'DAGS_FOLDER/cris.py', '--cfg-path', '/tmp/tmp3shtdf5_']
[2024-05-27T08:20:54.467+0000] {standard_task_runner.py:91} INFO - Job 12127: Subtask fetch_and_save_weather_data
[2024-05-27T08:20:54.520+0000] {task_command.py:426} INFO - Running <TaskInstance: fetch_parse_store_report_weather_data.fetch_and_save_weather_data scheduled__2024-05-23T11:00:00+00:00 [running]> on host b151419bfa2a
[2024-05-27T08:20:54.624+0000] {taskinstance.py:2644} INFO - Exporting env vars: AIRFLOW_CTX_DAG_OWNER='***' AIRFLOW_CTX_DAG_ID='fetch_parse_store_report_weather_data' AIRFLOW_CTX_TASK_ID='fetch_and_save_weather_data' AIRFLOW_CTX_EXECUTION_DATE='2024-05-23T11:00:00+00:00' AIRFLOW_CTX_TRY_NUMBER='1' AIRFLOW_CTX_DAG_RUN_ID='scheduled__2024-05-23T11:00:00+00:00'
[2024-05-27T08:20:54.627+0000] {taskinstance.py:430} INFO - ::endgroup::
[2024-05-27T08:21:01.319+0000] {taskinstance.py:441} INFO - ::group::Post task execution logs
[2024-05-27T08:21:01.320+0000] {taskinstance.py:2890} ERROR - Task failed with exception
Traceback (most recent call last):
  File "/home/airflow/.local/lib/python3.12/site-packages/airflow/models/taskinstance.py", line 465, in _execute_task
    result = _execute_callable(context=context, **execute_callable_kwargs)
             ^^^^^^^^^^^^^^^^^^^^^^^^^^^^^^^^^^^^^^^^^^^^^^^^^^^^^^^^^^^^^
  File "/home/airflow/.local/lib/python3.12/site-packages/airflow/models/taskinstance.py", line 432, in _execute_callable
    return execute_callable(context=context, **execute_callable_kwargs)
           ^^^^^^^^^^^^^^^^^^^^^^^^^^^^^^^^^^^^^^^^^^^^^^^^^^^^^^^^^^^^
  File "/home/airflow/.local/lib/python3.12/site-packages/airflow/models/baseoperator.py", line 400, in wrapper
    return func(self, *args, **kwargs)
           ^^^^^^^^^^^^^^^^^^^^^^^^^^^
  File "/home/airflow/.local/lib/python3.12/site-packages/airflow/operators/python.py", line 235, in execute
    return_value = self.execute_callable()
                   ^^^^^^^^^^^^^^^^^^^^^^^
  File "/home/airflow/.local/lib/python3.12/site-packages/airflow/operators/python.py", line 252, in execute_callable
    return self.python_callable(*self.op_args, **self.op_kwargs)
           ^^^^^^^^^^^^^^^^^^^^^^^^^^^^^^^^^^^^^^^^^^^^^^^^^^^^^
  File "/opt/airflow/dags/cris.py", line 40, in fetch_and_save_weather_data
    existing_data = json.load(f)
                    ^^^^^^^^^^^^
  File "/usr/local/lib/python3.12/json/__init__.py", line 293, in load
    return loads(fp.read(),
           ^^^^^^^^^^^^^^^^
  File "/usr/local/lib/python3.12/json/__init__.py", line 346, in loads
    return _default_decoder.decode(s)
           ^^^^^^^^^^^^^^^^^^^^^^^^^^
  File "/usr/local/lib/python3.12/json/decoder.py", line 337, in decode
    obj, end = self.raw_decode(s, idx=_w(s, 0).end())
               ^^^^^^^^^^^^^^^^^^^^^^^^^^^^^^^^^^^^^^
  File "/usr/local/lib/python3.12/json/decoder.py", line 353, in raw_decode
    obj, end = self.scan_once(s, idx)
               ^^^^^^^^^^^^^^^^^^^^^^
json.decoder.JSONDecodeError: Expecting property name enclosed in double quotes: line 1 column 24573 (char 24572)
[2024-05-27T08:21:01.360+0000] {taskinstance.py:1205} INFO - Marking task as UP_FOR_RETRY. dag_id=fetch_parse_store_report_weather_data, task_id=fetch_and_save_weather_data, execution_date=20240523T110000, start_date=20240527T082054, end_date=20240527T082101
[2024-05-27T08:21:01.397+0000] {standard_task_runner.py:110} ERROR - Failed to execute job 12127 for task fetch_and_save_weather_data (Expecting property name enclosed in double quotes: line 1 column 24573 (char 24572); 20095)
[2024-05-27T08:21:01.442+0000] {local_task_job_runner.py:240} INFO - Task exited with return code 1
[2024-05-27T08:21:01.784+0000] {taskinstance.py:3482} INFO - 0 downstream tasks scheduled from follow-on schedule check
[2024-05-27T08:21:01.802+0000] {local_task_job_runner.py:222} INFO - ::endgroup::
