[2024-05-19T12:52:47.647+0000] {local_task_job_runner.py:120} INFO - ::group::Pre task execution logs
[2024-05-19T12:52:47.682+0000] {taskinstance.py:2073} INFO - Dependencies all met for dep_context=non-requeueable deps ti=<TaskInstance: fetch_parse_store_report_weather_data.send_report_to_telegram scheduled__2024-05-05T10:00:00+00:00 [queued]>
[2024-05-19T12:52:47.694+0000] {taskinstance.py:2073} INFO - Dependencies all met for dep_context=requeueable deps ti=<TaskInstance: fetch_parse_store_report_weather_data.send_report_to_telegram scheduled__2024-05-05T10:00:00+00:00 [queued]>
[2024-05-19T12:52:47.696+0000] {taskinstance.py:2303} INFO - Starting attempt 1 of 2
[2024-05-19T12:52:47.716+0000] {taskinstance.py:2327} INFO - Executing <Task(PythonOperator): send_report_to_telegram> on 2024-05-05 10:00:00+00:00
[2024-05-19T12:52:47.726+0000] {warnings.py:110} WARNING - /home/***/.local/lib/python3.12/site-packages/***/task/task_runner/standard_task_runner.py:61: DeprecationWarning: This process (pid=1561) is multi-threaded, use of fork() may lead to deadlocks in the child.
  pid = os.fork()

[2024-05-19T12:52:47.728+0000] {standard_task_runner.py:63} INFO - Started process 1572 to run task
[2024-05-19T12:52:47.728+0000] {standard_task_runner.py:90} INFO - Running: ['***', 'tasks', 'run', 'fetch_parse_store_report_weather_data', 'send_report_to_telegram', 'scheduled__2024-05-05T10:00:00+00:00', '--job-id', '5617', '--raw', '--subdir', 'DAGS_FOLDER/cris.py', '--cfg-path', '/tmp/tmp0gh85rh6']
[2024-05-19T12:52:47.729+0000] {standard_task_runner.py:91} INFO - Job 5617: Subtask send_report_to_telegram
[2024-05-19T12:52:47.804+0000] {task_command.py:426} INFO - Running <TaskInstance: fetch_parse_store_report_weather_data.send_report_to_telegram scheduled__2024-05-05T10:00:00+00:00 [running]> on host d2eb9883ca8d
[2024-05-19T12:52:48.232+0000] {taskinstance.py:2644} INFO - Exporting env vars: AIRFLOW_CTX_DAG_OWNER='***' AIRFLOW_CTX_DAG_ID='fetch_parse_store_report_weather_data' AIRFLOW_CTX_TASK_ID='send_report_to_telegram' AIRFLOW_CTX_EXECUTION_DATE='2024-05-05T10:00:00+00:00' AIRFLOW_CTX_TRY_NUMBER='1' AIRFLOW_CTX_DAG_RUN_ID='scheduled__2024-05-05T10:00:00+00:00'
[2024-05-19T12:52:48.235+0000] {taskinstance.py:430} INFO - ::endgroup::
[2024-05-19T12:52:48.236+0000] {taskinstance.py:441} INFO - ::group::Post task execution logs
[2024-05-19T12:52:48.237+0000] {taskinstance.py:2890} ERROR - Task failed with exception
Traceback (most recent call last):
  File "/home/airflow/.local/lib/python3.12/site-packages/airflow/models/taskinstance.py", line 465, in _execute_task
    result = _execute_callable(context=context, **execute_callable_kwargs)
             ^^^^^^^^^^^^^^^^^^^^^^^^^^^^^^^^^^^^^^^^^^^^^^^^^^^^^^^^^^^^^
  File "/home/airflow/.local/lib/python3.12/site-packages/airflow/models/taskinstance.py", line 432, in _execute_callable
    return execute_callable(context=context, **execute_callable_kwargs)
           ^^^^^^^^^^^^^^^^^^^^^^^^^^^^^^^^^^^^^^^^^^^^^^^^^^^^^^^^^^^^
  File "/home/airflow/.local/lib/python3.12/site-packages/airflow/models/baseoperator.py", line 400, in wrapper
    return func(self, *args, **kwargs)
           ^^^^^^^^^^^^^^^^^^^^^^^^^^^
  File "/home/airflow/.local/lib/python3.12/site-packages/airflow/operators/python.py", line 235, in execute
    return_value = self.execute_callable()
                   ^^^^^^^^^^^^^^^^^^^^^^^
  File "/home/airflow/.local/lib/python3.12/site-packages/airflow/operators/python.py", line 252, in execute_callable
    return self.python_callable(*self.op_args, **self.op_kwargs)
           ^^^^^^^^^^^^^^^^^^^^^^^^^^^^^^^^^^^^^^^^^^^^^^^^^^^^^
  File "/opt/airflow/dags/cris.py", line 171, in send_report_to_telegram
    with open(file, 'rb') as f:
         ^^^^^^^^^^^^^^^^
FileNotFoundError: [Errno 2] No such file or directory: '/tmp/report.txt'
[2024-05-19T12:52:48.251+0000] {taskinstance.py:1205} INFO - Marking task as UP_FOR_RETRY. dag_id=fetch_parse_store_report_weather_data, task_id=send_report_to_telegram, execution_date=20240505T100000, start_date=20240519T125247, end_date=20240519T125248
[2024-05-19T12:52:48.270+0000] {standard_task_runner.py:110} ERROR - Failed to execute job 5617 for task send_report_to_telegram ([Errno 2] No such file or directory: '/tmp/report.txt'; 1572)
[2024-05-19T12:52:48.304+0000] {local_task_job_runner.py:240} INFO - Task exited with return code 1
[2024-05-19T12:52:48.327+0000] {taskinstance.py:3482} INFO - 0 downstream tasks scheduled from follow-on schedule check
[2024-05-19T12:52:48.329+0000] {local_task_job_runner.py:222} INFO - ::endgroup::
