[2024-05-19T12:57:13.575+0000] {local_task_job_runner.py:120} INFO - ::group::Pre task execution logs
[2024-05-19T12:57:13.598+0000] {taskinstance.py:2073} INFO - Dependencies all met for dep_context=non-requeueable deps ti=<TaskInstance: fetch_parse_store_report_weather_data.send_report_to_telegram scheduled__2024-05-05T13:00:00+00:00 [queued]>
[2024-05-19T12:57:13.607+0000] {taskinstance.py:2073} INFO - Dependencies all met for dep_context=requeueable deps ti=<TaskInstance: fetch_parse_store_report_weather_data.send_report_to_telegram scheduled__2024-05-05T13:00:00+00:00 [queued]>
[2024-05-19T12:57:13.608+0000] {taskinstance.py:2303} INFO - Starting attempt 1 of 2
[2024-05-19T12:57:13.622+0000] {taskinstance.py:2327} INFO - Executing <Task(PythonOperator): send_report_to_telegram> on 2024-05-05 13:00:00+00:00
[2024-05-19T12:57:13.630+0000] {warnings.py:110} WARNING - /home/***/.local/lib/python3.12/site-packages/***/task/task_runner/standard_task_runner.py:61: DeprecationWarning: This process (pid=1666) is multi-threaded, use of fork() may lead to deadlocks in the child.
  pid = os.fork()

[2024-05-19T12:57:13.632+0000] {standard_task_runner.py:63} INFO - Started process 1673 to run task
[2024-05-19T12:57:13.632+0000] {standard_task_runner.py:90} INFO - Running: ['***', 'tasks', 'run', 'fetch_parse_store_report_weather_data', 'send_report_to_telegram', 'scheduled__2024-05-05T13:00:00+00:00', '--job-id', '5634', '--raw', '--subdir', 'DAGS_FOLDER/cris.py', '--cfg-path', '/tmp/tmp1sw4rmmq']
[2024-05-19T12:57:13.634+0000] {standard_task_runner.py:91} INFO - Job 5634: Subtask send_report_to_telegram
[2024-05-19T12:57:13.680+0000] {task_command.py:426} INFO - Running <TaskInstance: fetch_parse_store_report_weather_data.send_report_to_telegram scheduled__2024-05-05T13:00:00+00:00 [running]> on host d2eb9883ca8d
[2024-05-19T12:57:13.982+0000] {taskinstance.py:2644} INFO - Exporting env vars: AIRFLOW_CTX_DAG_OWNER='***' AIRFLOW_CTX_DAG_ID='fetch_parse_store_report_weather_data' AIRFLOW_CTX_TASK_ID='send_report_to_telegram' AIRFLOW_CTX_EXECUTION_DATE='2024-05-05T13:00:00+00:00' AIRFLOW_CTX_TRY_NUMBER='1' AIRFLOW_CTX_DAG_RUN_ID='scheduled__2024-05-05T13:00:00+00:00'
[2024-05-19T12:57:13.984+0000] {taskinstance.py:430} INFO - ::endgroup::
[2024-05-19T12:57:13.985+0000] {taskinstance.py:441} INFO - ::group::Post task execution logs
[2024-05-19T12:57:13.985+0000] {taskinstance.py:2890} ERROR - Task failed with exception
Traceback (most recent call last):
  File "/home/airflow/.local/lib/python3.12/site-packages/airflow/models/taskinstance.py", line 465, in _execute_task
    result = _execute_callable(context=context, **execute_callable_kwargs)
             ^^^^^^^^^^^^^^^^^^^^^^^^^^^^^^^^^^^^^^^^^^^^^^^^^^^^^^^^^^^^^
  File "/home/airflow/.local/lib/python3.12/site-packages/airflow/models/taskinstance.py", line 432, in _execute_callable
    return execute_callable(context=context, **execute_callable_kwargs)
           ^^^^^^^^^^^^^^^^^^^^^^^^^^^^^^^^^^^^^^^^^^^^^^^^^^^^^^^^^^^^
  File "/home/airflow/.local/lib/python3.12/site-packages/airflow/models/baseoperator.py", line 400, in wrapper
    return func(self, *args, **kwargs)
           ^^^^^^^^^^^^^^^^^^^^^^^^^^^
  File "/home/airflow/.local/lib/python3.12/site-packages/airflow/operators/python.py", line 235, in execute
    return_value = self.execute_callable()
                   ^^^^^^^^^^^^^^^^^^^^^^^
  File "/home/airflow/.local/lib/python3.12/site-packages/airflow/operators/python.py", line 252, in execute_callable
    return self.python_callable(*self.op_args, **self.op_kwargs)
           ^^^^^^^^^^^^^^^^^^^^^^^^^^^^^^^^^^^^^^^^^^^^^^^^^^^^^
  File "/opt/airflow/dags/cris.py", line 171, in send_report_to_telegram
    with open(file, 'rb') as f:
         ^^^^^^^^^^^^^^^^
FileNotFoundError: [Errno 2] No such file or directory: '/tmp/report.txt'
[2024-05-19T12:57:14.003+0000] {taskinstance.py:1205} INFO - Marking task as UP_FOR_RETRY. dag_id=fetch_parse_store_report_weather_data, task_id=send_report_to_telegram, execution_date=20240505T130000, start_date=20240519T125713, end_date=20240519T125714
[2024-05-19T12:57:14.023+0000] {standard_task_runner.py:110} ERROR - Failed to execute job 5634 for task send_report_to_telegram ([Errno 2] No such file or directory: '/tmp/report.txt'; 1673)
[2024-05-19T12:57:14.047+0000] {local_task_job_runner.py:240} INFO - Task exited with return code 1
[2024-05-19T12:57:14.128+0000] {taskinstance.py:3482} INFO - 0 downstream tasks scheduled from follow-on schedule check
[2024-05-19T12:57:14.130+0000] {local_task_job_runner.py:222} INFO - ::endgroup::
