[2024-04-17T00:17:26.081+0000] {local_task_job_runner.py:120} INFO - ::group::Pre task execution logs
[2024-04-17T00:17:26.155+0000] {taskinstance.py:2073} INFO - Dependencies all met for dep_context=non-requeueable deps ti=<TaskInstance: fetch_and_parse_weather_data.fetch_and_save_weather_data scheduled__2024-04-16T14:00:00+00:00 [queued]>
[2024-04-17T00:17:26.172+0000] {taskinstance.py:2073} INFO - Dependencies all met for dep_context=requeueable deps ti=<TaskInstance: fetch_and_parse_weather_data.fetch_and_save_weather_data scheduled__2024-04-16T14:00:00+00:00 [queued]>
[2024-04-17T00:17:26.173+0000] {taskinstance.py:2303} INFO - Starting attempt 1 of 2
[2024-04-17T00:17:26.232+0000] {taskinstance.py:2327} INFO - Executing <Task(PythonOperator): fetch_and_save_weather_data> on 2024-04-16 14:00:00+00:00
[2024-04-17T00:17:26.260+0000] {warnings.py:110} WARNING - /home/***/.local/lib/python3.12/site-packages/***/task/task_runner/standard_task_runner.py:61: DeprecationWarning: This process (pid=5190) is multi-threaded, use of fork() may lead to deadlocks in the child.
  pid = os.fork()

[2024-04-17T00:17:26.264+0000] {standard_task_runner.py:63} INFO - Started process 5221 to run task
[2024-04-17T00:17:26.284+0000] {standard_task_runner.py:90} INFO - Running: ['***', 'tasks', 'run', 'fetch_and_parse_weather_data', 'fetch_and_save_weather_data', 'scheduled__2024-04-16T14:00:00+00:00', '--job-id', '115', '--raw', '--subdir', 'DAGS_FOLDER/json_dag.py', '--cfg-path', '/tmp/tmpa6x9ua8r']
[2024-04-17T00:17:26.299+0000] {standard_task_runner.py:91} INFO - Job 115: Subtask fetch_and_save_weather_data
[2024-04-17T00:17:26.538+0000] {task_command.py:426} INFO - Running <TaskInstance: fetch_and_parse_weather_data.fetch_and_save_weather_data scheduled__2024-04-16T14:00:00+00:00 [running]> on host e8691f41e037
[2024-04-17T00:17:26.992+0000] {taskinstance.py:2644} INFO - Exporting env vars: AIRFLOW_CTX_DAG_OWNER='***' AIRFLOW_CTX_DAG_ID='fetch_and_parse_weather_data' AIRFLOW_CTX_TASK_ID='fetch_and_save_weather_data' AIRFLOW_CTX_EXECUTION_DATE='2024-04-16T14:00:00+00:00' AIRFLOW_CTX_TRY_NUMBER='1' AIRFLOW_CTX_DAG_RUN_ID='scheduled__2024-04-16T14:00:00+00:00'
[2024-04-17T00:17:27.001+0000] {taskinstance.py:430} INFO - ::endgroup::
[2024-04-17T00:17:27.016+0000] {taskinstance.py:441} INFO - ::group::Post task execution logs
[2024-04-17T00:17:27.020+0000] {taskinstance.py:2890} ERROR - Task failed with exception
Traceback (most recent call last):
  File "/home/airflow/.local/lib/python3.12/site-packages/urllib3/connection.py", line 174, in _new_conn
    conn = connection.create_connection(
           ^^^^^^^^^^^^^^^^^^^^^^^^^^^^^
  File "/home/airflow/.local/lib/python3.12/site-packages/urllib3/util/connection.py", line 72, in create_connection
    for res in socket.getaddrinfo(host, port, family, socket.SOCK_STREAM):
               ^^^^^^^^^^^^^^^^^^^^^^^^^^^^^^^^^^^^^^^^^^^^^^^^^^^^^^^^^^
  File "/usr/local/lib/python3.12/socket.py", line 963, in getaddrinfo
    for res in _socket.getaddrinfo(host, port, family, type, proto, flags):
               ^^^^^^^^^^^^^^^^^^^^^^^^^^^^^^^^^^^^^^^^^^^^^^^^^^^^^^^^^^^
socket.gaierror: [Errno -2] Name or service not known

During handling of the above exception, another exception occurred:

Traceback (most recent call last):
  File "/home/airflow/.local/lib/python3.12/site-packages/urllib3/connectionpool.py", line 715, in urlopen
    httplib_response = self._make_request(
                       ^^^^^^^^^^^^^^^^^^^
  File "/home/airflow/.local/lib/python3.12/site-packages/urllib3/connectionpool.py", line 416, in _make_request
    conn.request(method, url, **httplib_request_kw)
  File "/home/airflow/.local/lib/python3.12/site-packages/urllib3/connection.py", line 244, in request
    super(HTTPConnection, self).request(method, url, body=body, headers=headers)
  File "/usr/local/lib/python3.12/http/client.py", line 1331, in request
    self._send_request(method, url, body, headers, encode_chunked)
  File "/usr/local/lib/python3.12/http/client.py", line 1377, in _send_request
    self.endheaders(body, encode_chunked=encode_chunked)
  File "/usr/local/lib/python3.12/http/client.py", line 1326, in endheaders
    self._send_output(message_body, encode_chunked=encode_chunked)
  File "/usr/local/lib/python3.12/http/client.py", line 1085, in _send_output
    self.send(msg)
  File "/usr/local/lib/python3.12/http/client.py", line 1029, in send
    self.connect()
  File "/home/airflow/.local/lib/python3.12/site-packages/urllib3/connection.py", line 205, in connect
    conn = self._new_conn()
           ^^^^^^^^^^^^^^^^
  File "/home/airflow/.local/lib/python3.12/site-packages/urllib3/connection.py", line 186, in _new_conn
    raise NewConnectionError(
urllib3.exceptions.NewConnectionError: <urllib3.connection.HTTPConnection object at 0x7fbb2996f020>: Failed to establish a new connection: [Errno -2] Name or service not known

During handling of the above exception, another exception occurred:

Traceback (most recent call last):
  File "/home/airflow/.local/lib/python3.12/site-packages/requests/adapters.py", line 486, in send
    resp = conn.urlopen(
           ^^^^^^^^^^^^^
  File "/home/airflow/.local/lib/python3.12/site-packages/urllib3/connectionpool.py", line 799, in urlopen
    retries = retries.increment(
              ^^^^^^^^^^^^^^^^^^
  File "/home/airflow/.local/lib/python3.12/site-packages/urllib3/util/retry.py", line 592, in increment
    raise MaxRetryError(_pool, url, error or ResponseError(cause))
urllib3.exceptions.MaxRetryError: HTTPConnectionPool(host='geos.icc.ru', port=8080): Max retries exceeded with url: /weather (Caused by NewConnectionError('<urllib3.connection.HTTPConnection object at 0x7fbb2996f020>: Failed to establish a new connection: [Errno -2] Name or service not known'))

During handling of the above exception, another exception occurred:

Traceback (most recent call last):
  File "/home/airflow/.local/lib/python3.12/site-packages/airflow/models/taskinstance.py", line 465, in _execute_task
    result = _execute_callable(context=context, **execute_callable_kwargs)
             ^^^^^^^^^^^^^^^^^^^^^^^^^^^^^^^^^^^^^^^^^^^^^^^^^^^^^^^^^^^^^
  File "/home/airflow/.local/lib/python3.12/site-packages/airflow/models/taskinstance.py", line 432, in _execute_callable
    return execute_callable(context=context, **execute_callable_kwargs)
           ^^^^^^^^^^^^^^^^^^^^^^^^^^^^^^^^^^^^^^^^^^^^^^^^^^^^^^^^^^^^
  File "/home/airflow/.local/lib/python3.12/site-packages/airflow/models/baseoperator.py", line 400, in wrapper
    return func(self, *args, **kwargs)
           ^^^^^^^^^^^^^^^^^^^^^^^^^^^
  File "/home/airflow/.local/lib/python3.12/site-packages/airflow/operators/python.py", line 235, in execute
    return_value = self.execute_callable()
                   ^^^^^^^^^^^^^^^^^^^^^^^
  File "/home/airflow/.local/lib/python3.12/site-packages/airflow/operators/python.py", line 252, in execute_callable
    return self.python_callable(*self.op_args, **self.op_kwargs)
           ^^^^^^^^^^^^^^^^^^^^^^^^^^^^^^^^^^^^^^^^^^^^^^^^^^^^^
  File "/opt/airflow/dags/json_dag.py", line 23, in fetch_and_save_weather_data
    response = requests.get(url)
               ^^^^^^^^^^^^^^^^^
  File "/home/airflow/.local/lib/python3.12/site-packages/requests/api.py", line 73, in get
    return request("get", url, params=params, **kwargs)
           ^^^^^^^^^^^^^^^^^^^^^^^^^^^^^^^^^^^^^^^^^^^^
  File "/home/airflow/.local/lib/python3.12/site-packages/requests/api.py", line 59, in request
    return session.request(method=method, url=url, **kwargs)
           ^^^^^^^^^^^^^^^^^^^^^^^^^^^^^^^^^^^^^^^^^^^^^^^^^
  File "/home/airflow/.local/lib/python3.12/site-packages/requests/sessions.py", line 589, in request
    resp = self.send(prep, **send_kwargs)
           ^^^^^^^^^^^^^^^^^^^^^^^^^^^^^^
  File "/home/airflow/.local/lib/python3.12/site-packages/requests/sessions.py", line 703, in send
    r = adapter.send(request, **kwargs)
        ^^^^^^^^^^^^^^^^^^^^^^^^^^^^^^^
  File "/home/airflow/.local/lib/python3.12/site-packages/requests/adapters.py", line 519, in send
    raise ConnectionError(e, request=request)
requests.exceptions.ConnectionError: HTTPConnectionPool(host='geos.icc.ru', port=8080): Max retries exceeded with url: /weather (Caused by NewConnectionError('<urllib3.connection.HTTPConnection object at 0x7fbb2996f020>: Failed to establish a new connection: [Errno -2] Name or service not known'))
[2024-04-17T00:17:27.066+0000] {taskinstance.py:1205} INFO - Marking task as UP_FOR_RETRY. dag_id=fetch_and_parse_weather_data, task_id=fetch_and_save_weather_data, execution_date=20240416T140000, start_date=20240417T001726, end_date=20240417T001727
[2024-04-17T00:17:27.099+0000] {standard_task_runner.py:110} ERROR - Failed to execute job 115 for task fetch_and_save_weather_data (HTTPConnectionPool(host='geos.icc.ru', port=8080): Max retries exceeded with url: /weather (Caused by NewConnectionError('<urllib3.connection.HTTPConnection object at 0x7fbb2996f020>: Failed to establish a new connection: [Errno -2] Name or service not known')); 5221)
[2024-04-17T00:17:27.160+0000] {local_task_job_runner.py:240} INFO - Task exited with return code 1
[2024-04-17T00:17:27.196+0000] {taskinstance.py:3482} INFO - 0 downstream tasks scheduled from follow-on schedule check
[2024-04-17T00:17:27.217+0000] {local_task_job_runner.py:222} INFO - ::endgroup::
