[2024-05-19T11:40:27.911+0000] {local_task_job_runner.py:120} INFO - ::group::Pre task execution logs
[2024-05-19T11:40:27.978+0000] {taskinstance.py:2073} INFO - Dependencies all met for dep_context=non-requeueable deps ti=<TaskInstance: fetch_parse_store_report_weather_data.check_files_exist scheduled__2024-04-26T13:00:00+00:00 [queued]>
[2024-05-19T11:40:27.999+0000] {taskinstance.py:2073} INFO - Dependencies all met for dep_context=requeueable deps ti=<TaskInstance: fetch_parse_store_report_weather_data.check_files_exist scheduled__2024-04-26T13:00:00+00:00 [queued]>
[2024-05-19T11:40:28.001+0000] {taskinstance.py:2303} INFO - Starting attempt 2 of 2
[2024-05-19T11:40:28.043+0000] {taskinstance.py:2327} INFO - Executing <Task(PythonOperator): check_files_exist> on 2024-04-26 13:00:00+00:00
[2024-05-19T11:40:28.064+0000] {warnings.py:110} WARNING - /home/***/.local/lib/python3.12/site-packages/***/task/task_runner/standard_task_runner.py:61: DeprecationWarning: This process (pid=181) is multi-threaded, use of fork() may lead to deadlocks in the child.
  pid = os.fork()

[2024-05-19T11:40:28.067+0000] {standard_task_runner.py:63} INFO - Started process 207 to run task
[2024-05-19T11:40:28.076+0000] {standard_task_runner.py:90} INFO - Running: ['***', 'tasks', 'run', 'fetch_parse_store_report_weather_data', 'check_files_exist', 'scheduled__2024-04-26T13:00:00+00:00', '--job-id', '4611', '--raw', '--subdir', 'DAGS_FOLDER/cris.py', '--cfg-path', '/tmp/tmpv69o4r62']
[2024-05-19T11:40:28.077+0000] {standard_task_runner.py:91} INFO - Job 4611: Subtask check_files_exist
[2024-05-19T11:40:28.219+0000] {task_command.py:426} INFO - Running <TaskInstance: fetch_parse_store_report_weather_data.check_files_exist scheduled__2024-04-26T13:00:00+00:00 [running]> on host d2eb9883ca8d
[2024-05-19T11:40:29.287+0000] {taskinstance.py:2644} INFO - Exporting env vars: AIRFLOW_CTX_DAG_OWNER='***' AIRFLOW_CTX_DAG_ID='fetch_parse_store_report_weather_data' AIRFLOW_CTX_TASK_ID='check_files_exist' AIRFLOW_CTX_EXECUTION_DATE='2024-04-26T13:00:00+00:00' AIRFLOW_CTX_TRY_NUMBER='2' AIRFLOW_CTX_DAG_RUN_ID='scheduled__2024-04-26T13:00:00+00:00'
[2024-05-19T11:40:29.289+0000] {taskinstance.py:430} INFO - ::endgroup::
[2024-05-19T11:40:29.290+0000] {taskinstance.py:441} INFO - ::group::Post task execution logs
[2024-05-19T11:40:29.291+0000] {taskinstance.py:2890} ERROR - Task failed with exception
Traceback (most recent call last):
  File "/home/airflow/.local/lib/python3.12/site-packages/airflow/models/taskinstance.py", line 465, in _execute_task
    result = _execute_callable(context=context, **execute_callable_kwargs)
             ^^^^^^^^^^^^^^^^^^^^^^^^^^^^^^^^^^^^^^^^^^^^^^^^^^^^^^^^^^^^^
  File "/home/airflow/.local/lib/python3.12/site-packages/airflow/models/taskinstance.py", line 432, in _execute_callable
    return execute_callable(context=context, **execute_callable_kwargs)
           ^^^^^^^^^^^^^^^^^^^^^^^^^^^^^^^^^^^^^^^^^^^^^^^^^^^^^^^^^^^^
  File "/home/airflow/.local/lib/python3.12/site-packages/airflow/models/baseoperator.py", line 400, in wrapper
    return func(self, *args, **kwargs)
           ^^^^^^^^^^^^^^^^^^^^^^^^^^^
  File "/home/airflow/.local/lib/python3.12/site-packages/airflow/operators/python.py", line 235, in execute
    return_value = self.execute_callable()
                   ^^^^^^^^^^^^^^^^^^^^^^^
  File "/home/airflow/.local/lib/python3.12/site-packages/airflow/operators/python.py", line 252, in execute_callable
    return self.python_callable(*self.op_args, **self.op_kwargs)
           ^^^^^^^^^^^^^^^^^^^^^^^^^^^^^^^^^^^^^^^^^^^^^^^^^^^^^
  File "/opt/airflow/dags/cris.py", line 184, in check_files_exist
    raise FileNotFoundError(f"File {file} does not exist")
FileNotFoundError: File /tmp/report.txt does not exist
[2024-05-19T11:40:29.339+0000] {taskinstance.py:1205} INFO - Marking task as FAILED. dag_id=fetch_parse_store_report_weather_data, task_id=check_files_exist, execution_date=20240426T130000, start_date=20240519T114027, end_date=20240519T114029
[2024-05-19T11:40:29.399+0000] {standard_task_runner.py:110} ERROR - Failed to execute job 4611 for task check_files_exist (File /tmp/report.txt does not exist; 207)
[2024-05-19T11:40:29.491+0000] {local_task_job_runner.py:240} INFO - Task exited with return code 1
[2024-05-19T11:40:29.555+0000] {taskinstance.py:3482} INFO - 0 downstream tasks scheduled from follow-on schedule check
[2024-05-19T11:40:29.577+0000] {local_task_job_runner.py:222} INFO - ::endgroup::
