[2024-05-18T14:13:24.547+0000] {local_task_job_runner.py:120} INFO - ::group::Pre task execution logs
[2024-05-18T14:13:24.583+0000] {taskinstance.py:2073} INFO - Dependencies all met for dep_context=non-requeueable deps ti=<TaskInstance: fetch_parse_store_report_weather_data.send_email scheduled__2024-04-23T06:00:00+00:00 [queued]>
[2024-05-18T14:13:24.599+0000] {taskinstance.py:2073} INFO - Dependencies all met for dep_context=requeueable deps ti=<TaskInstance: fetch_parse_store_report_weather_data.send_email scheduled__2024-04-23T06:00:00+00:00 [queued]>
[2024-05-18T14:13:24.600+0000] {taskinstance.py:2303} INFO - Starting attempt 1 of 2
[2024-05-18T14:13:24.623+0000] {taskinstance.py:2327} INFO - Executing <Task(EmailOperator): send_email> on 2024-04-23 06:00:00+00:00
[2024-05-18T14:13:24.635+0000] {warnings.py:110} WARNING - /home/***/.local/lib/python3.12/site-packages/***/task/task_runner/standard_task_runner.py:61: DeprecationWarning: This process (pid=4023) is multi-threaded, use of fork() may lead to deadlocks in the child.
  pid = os.fork()

[2024-05-18T14:13:24.638+0000] {standard_task_runner.py:63} INFO - Started process 4044 to run task
[2024-05-18T14:13:24.638+0000] {standard_task_runner.py:90} INFO - Running: ['***', 'tasks', 'run', 'fetch_parse_store_report_weather_data', 'send_email', 'scheduled__2024-04-23T06:00:00+00:00', '--job-id', '4098', '--raw', '--subdir', 'DAGS_FOLDER/cris.py', '--cfg-path', '/tmp/tmp8nxa8rvb']
[2024-05-18T14:13:24.640+0000] {standard_task_runner.py:91} INFO - Job 4098: Subtask send_email
[2024-05-18T14:13:24.712+0000] {task_command.py:426} INFO - Running <TaskInstance: fetch_parse_store_report_weather_data.send_email scheduled__2024-04-23T06:00:00+00:00 [running]> on host d2eb9883ca8d
[2024-05-18T14:13:24.866+0000] {taskinstance.py:2644} INFO - Exporting env vars: AIRFLOW_CTX_DAG_OWNER='***' AIRFLOW_CTX_DAG_ID='fetch_parse_store_report_weather_data' AIRFLOW_CTX_TASK_ID='send_email' AIRFLOW_CTX_EXECUTION_DATE='2024-04-23T06:00:00+00:00' AIRFLOW_CTX_TRY_NUMBER='1' AIRFLOW_CTX_DAG_RUN_ID='scheduled__2024-04-23T06:00:00+00:00'
[2024-05-18T14:13:24.869+0000] {taskinstance.py:430} INFO - ::endgroup::
[2024-05-18T14:13:24.872+0000] {taskinstance.py:441} INFO - ::group::Post task execution logs
[2024-05-18T14:13:24.873+0000] {taskinstance.py:2890} ERROR - Task failed with exception
Traceback (most recent call last):
  File "/home/airflow/.local/lib/python3.12/site-packages/airflow/models/taskinstance.py", line 465, in _execute_task
    result = _execute_callable(context=context, **execute_callable_kwargs)
             ^^^^^^^^^^^^^^^^^^^^^^^^^^^^^^^^^^^^^^^^^^^^^^^^^^^^^^^^^^^^^
  File "/home/airflow/.local/lib/python3.12/site-packages/airflow/models/taskinstance.py", line 432, in _execute_callable
    return execute_callable(context=context, **execute_callable_kwargs)
           ^^^^^^^^^^^^^^^^^^^^^^^^^^^^^^^^^^^^^^^^^^^^^^^^^^^^^^^^^^^^
  File "/home/airflow/.local/lib/python3.12/site-packages/airflow/models/baseoperator.py", line 400, in wrapper
    return func(self, *args, **kwargs)
           ^^^^^^^^^^^^^^^^^^^^^^^^^^^
  File "/home/airflow/.local/lib/python3.12/site-packages/airflow/operators/email.py", line 79, in execute
    send_email(
  File "/home/airflow/.local/lib/python3.12/site-packages/airflow/utils/email.py", line 80, in send_email
    return backend(
           ^^^^^^^^
  File "/home/airflow/.local/lib/python3.12/site-packages/airflow/utils/email.py", line 141, in send_email_smtp
    msg, recipients = build_mime_message(
                      ^^^^^^^^^^^^^^^^^^^
  File "/home/airflow/.local/lib/python3.12/site-packages/airflow/utils/email.py", line 209, in build_mime_message
    with open(fname, "rb") as file:
         ^^^^^^^^^^^^^^^^^
FileNotFoundError: [Errno 2] No such file or directory: '/tmp/report.txt'
[2024-05-18T14:13:24.888+0000] {taskinstance.py:1205} INFO - Marking task as UP_FOR_RETRY. dag_id=fetch_parse_store_report_weather_data, task_id=send_email, execution_date=20240423T060000, start_date=20240518T141324, end_date=20240518T141324
[2024-05-18T14:13:24.909+0000] {standard_task_runner.py:110} ERROR - Failed to execute job 4098 for task send_email ([Errno 2] No such file or directory: '/tmp/report.txt'; 4044)
[2024-05-18T14:13:24.936+0000] {local_task_job_runner.py:240} INFO - Task exited with return code 1
[2024-05-18T14:13:24.972+0000] {taskinstance.py:3482} INFO - 0 downstream tasks scheduled from follow-on schedule check
[2024-05-18T14:13:24.977+0000] {local_task_job_runner.py:222} INFO - ::endgroup::
