[2024-05-27T05:34:48.747+0000] {local_task_job_runner.py:120} INFO - ::group::Pre task execution logs
[2024-05-27T05:34:48.909+0000] {taskinstance.py:2073} INFO - Dependencies all met for dep_context=non-requeueable deps ti=<TaskInstance: train_lstm_model.train_model scheduled__2024-05-26T00:00:00+00:00 [queued]>
[2024-05-27T05:34:48.947+0000] {taskinstance.py:2073} INFO - Dependencies all met for dep_context=requeueable deps ti=<TaskInstance: train_lstm_model.train_model scheduled__2024-05-26T00:00:00+00:00 [queued]>
[2024-05-27T05:34:48.948+0000] {taskinstance.py:2303} INFO - Starting attempt 1 of 2
[2024-05-27T05:34:51.882+0000] {taskinstance.py:2327} INFO - Executing <Task(PythonOperator): train_model> on 2024-05-26 00:00:00+00:00
[2024-05-27T05:34:51.925+0000] {standard_task_runner.py:90} INFO - Running: ['***', 'tasks', 'run', 'train_lstm_model', 'train_model', 'scheduled__2024-05-26T00:00:00+00:00', '--job-id', '9732', '--raw', '--subdir', 'DAGS_FOLDER/model_dag.py', '--cfg-path', '/tmp/tmpt8jzi9py']
[2024-05-27T05:34:51.923+0000] {warnings.py:110} WARNING - /home/***/.local/lib/python3.12/site-packages/***/task/task_runner/standard_task_runner.py:61: DeprecationWarning: This process (pid=303) is multi-threaded, use of fork() may lead to deadlocks in the child.
  pid = os.fork()

[2024-05-27T05:34:51.936+0000] {standard_task_runner.py:63} INFO - Started process 445 to run task
[2024-05-27T05:34:51.933+0000] {standard_task_runner.py:91} INFO - Job 9732: Subtask train_model
[2024-05-27T05:34:52.205+0000] {task_command.py:426} INFO - Running <TaskInstance: train_lstm_model.train_model scheduled__2024-05-26T00:00:00+00:00 [running]> on host b151419bfa2a
[2024-05-27T05:34:52.594+0000] {taskinstance.py:2644} INFO - Exporting env vars: AIRFLOW_CTX_DAG_OWNER='***' AIRFLOW_CTX_DAG_ID='train_lstm_model' AIRFLOW_CTX_TASK_ID='train_model' AIRFLOW_CTX_EXECUTION_DATE='2024-05-26T00:00:00+00:00' AIRFLOW_CTX_TRY_NUMBER='1' AIRFLOW_CTX_DAG_RUN_ID='scheduled__2024-05-26T00:00:00+00:00'
[2024-05-27T05:34:52.596+0000] {taskinstance.py:430} INFO - ::endgroup::
[2024-05-27T05:34:52.683+0000] {base.py:84} INFO - Using connection ID 'postgres_default' for task execution.
[2024-05-27T05:34:52.736+0000] {taskinstance.py:441} INFO - ::group::Post task execution logs
[2024-05-27T05:34:52.737+0000] {taskinstance.py:2890} ERROR - Task failed with exception
Traceback (most recent call last):
  File "/home/airflow/.local/lib/python3.12/site-packages/airflow/models/taskinstance.py", line 465, in _execute_task
    result = _execute_callable(context=context, **execute_callable_kwargs)
             ^^^^^^^^^^^^^^^^^^^^^^^^^^^^^^^^^^^^^^^^^^^^^^^^^^^^^^^^^^^^^
  File "/home/airflow/.local/lib/python3.12/site-packages/airflow/models/taskinstance.py", line 432, in _execute_callable
    return execute_callable(context=context, **execute_callable_kwargs)
           ^^^^^^^^^^^^^^^^^^^^^^^^^^^^^^^^^^^^^^^^^^^^^^^^^^^^^^^^^^^^
  File "/home/airflow/.local/lib/python3.12/site-packages/airflow/models/baseoperator.py", line 400, in wrapper
    return func(self, *args, **kwargs)
           ^^^^^^^^^^^^^^^^^^^^^^^^^^^
  File "/home/airflow/.local/lib/python3.12/site-packages/airflow/operators/python.py", line 235, in execute
    return_value = self.execute_callable()
                   ^^^^^^^^^^^^^^^^^^^^^^^
  File "/home/airflow/.local/lib/python3.12/site-packages/airflow/operators/python.py", line 252, in execute_callable
    return self.python_callable(*self.op_args, **self.op_kwargs)
           ^^^^^^^^^^^^^^^^^^^^^^^^^^^^^^^^^^^^^^^^^^^^^^^^^^^^^
  File "/opt/airflow/dags/model_dag.py", line 36, in train_model
    pg_conn = pg_hook.get_conn()
              ^^^^^^^^^^^^^^^^^^
  File "/home/airflow/.local/lib/python3.12/site-packages/airflow/providers/postgres/hooks/postgres.py", line 161, in get_conn
    self.conn = psycopg2.connect(**conn_args)
                ^^^^^^^^^^^^^^^^^^^^^^^^^^^^^
  File "/home/airflow/.local/lib/python3.12/site-packages/psycopg2/__init__.py", line 122, in connect
    conn = _connect(dsn, connection_factory=connection_factory, **kwasync)
           ^^^^^^^^^^^^^^^^^^^^^^^^^^^^^^^^^^^^^^^^^^^^^^^^^^^^^^^^^^^^^^^
psycopg2.OperationalError: connection to server at "postgres" (172.21.0.4), port 5432 failed: FATAL:  database "weather_data" does not exist

[2024-05-27T05:34:52.796+0000] {taskinstance.py:1205} INFO - Marking task as UP_FOR_RETRY. dag_id=train_lstm_model, task_id=train_model, execution_date=20240526T000000, start_date=20240527T053448, end_date=20240527T053452
[2024-05-27T05:34:52.971+0000] {standard_task_runner.py:110} ERROR - Failed to execute job 9732 for task train_model (connection to server at "postgres" (172.21.0.4), port 5432 failed: FATAL:  database "weather_data" does not exist
; 445)
[2024-05-27T05:34:53.055+0000] {local_task_job_runner.py:240} INFO - Task exited with return code 1
[2024-05-27T05:34:53.109+0000] {taskinstance.py:3482} INFO - 0 downstream tasks scheduled from follow-on schedule check
[2024-05-27T05:34:53.127+0000] {local_task_job_runner.py:222} INFO - ::endgroup::
