[2024-05-18T13:06:34.072+0000] {local_task_job_runner.py:120} INFO - ::group::Pre task execution logs
[2024-05-18T13:06:34.132+0000] {taskinstance.py:2073} INFO - Dependencies all met for dep_context=non-requeueable deps ti=<TaskInstance: fetch_parse_store_report_weather_data.generate_report scheduled__2024-04-15T03:00:00+00:00 [queued]>
[2024-05-18T13:06:34.151+0000] {taskinstance.py:2073} INFO - Dependencies all met for dep_context=requeueable deps ti=<TaskInstance: fetch_parse_store_report_weather_data.generate_report scheduled__2024-04-15T03:00:00+00:00 [queued]>
[2024-05-18T13:06:34.153+0000] {taskinstance.py:2303} INFO - Starting attempt 1 of 2
[2024-05-18T13:06:34.182+0000] {taskinstance.py:2327} INFO - Executing <Task(PythonOperator): generate_report> on 2024-04-15 03:00:00+00:00
[2024-05-18T13:06:34.197+0000] {warnings.py:110} WARNING - /home/***/.local/lib/python3.12/site-packages/***/task/task_runner/standard_task_runner.py:61: DeprecationWarning: This process (pid=569) is multi-threaded, use of fork() may lead to deadlocks in the child.
  pid = os.fork()

[2024-05-18T13:06:34.201+0000] {standard_task_runner.py:63} INFO - Started process 590 to run task
[2024-05-18T13:06:34.200+0000] {standard_task_runner.py:90} INFO - Running: ['***', 'tasks', 'run', 'fetch_parse_store_report_weather_data', 'generate_report', 'scheduled__2024-04-15T03:00:00+00:00', '--job-id', '3227', '--raw', '--subdir', 'DAGS_FOLDER/cris.py', '--cfg-path', '/tmp/tmpb93mznxk']
[2024-05-18T13:06:34.202+0000] {standard_task_runner.py:91} INFO - Job 3227: Subtask generate_report
[2024-05-18T13:06:34.325+0000] {task_command.py:426} INFO - Running <TaskInstance: fetch_parse_store_report_weather_data.generate_report scheduled__2024-04-15T03:00:00+00:00 [running]> on host d2eb9883ca8d
[2024-05-18T13:06:35.651+0000] {taskinstance.py:2644} INFO - Exporting env vars: AIRFLOW_CTX_DAG_OWNER='***' AIRFLOW_CTX_DAG_ID='fetch_parse_store_report_weather_data' AIRFLOW_CTX_TASK_ID='generate_report' AIRFLOW_CTX_EXECUTION_DATE='2024-04-15T03:00:00+00:00' AIRFLOW_CTX_TRY_NUMBER='1' AIRFLOW_CTX_DAG_RUN_ID='scheduled__2024-04-15T03:00:00+00:00'
[2024-05-18T13:06:35.676+0000] {taskinstance.py:430} INFO - ::endgroup::
[2024-05-18T13:06:35.796+0000] {base.py:84} INFO - Using connection ID 'postgres_default' for task execution.
[2024-05-18T13:06:35.816+0000] {taskinstance.py:441} INFO - ::group::Post task execution logs
[2024-05-18T13:06:35.820+0000] {taskinstance.py:2890} ERROR - Task failed with exception
Traceback (most recent call last):
  File "/home/airflow/.local/lib/python3.12/site-packages/airflow/models/taskinstance.py", line 465, in _execute_task
    result = _execute_callable(context=context, **execute_callable_kwargs)
             ^^^^^^^^^^^^^^^^^^^^^^^^^^^^^^^^^^^^^^^^^^^^^^^^^^^^^^^^^^^^^
  File "/home/airflow/.local/lib/python3.12/site-packages/airflow/models/taskinstance.py", line 432, in _execute_callable
    return execute_callable(context=context, **execute_callable_kwargs)
           ^^^^^^^^^^^^^^^^^^^^^^^^^^^^^^^^^^^^^^^^^^^^^^^^^^^^^^^^^^^^
  File "/home/airflow/.local/lib/python3.12/site-packages/airflow/models/baseoperator.py", line 400, in wrapper
    return func(self, *args, **kwargs)
           ^^^^^^^^^^^^^^^^^^^^^^^^^^^
  File "/home/airflow/.local/lib/python3.12/site-packages/airflow/operators/python.py", line 235, in execute
    return_value = self.execute_callable()
                   ^^^^^^^^^^^^^^^^^^^^^^^
  File "/home/airflow/.local/lib/python3.12/site-packages/airflow/operators/python.py", line 252, in execute_callable
    return self.python_callable(*self.op_args, **self.op_kwargs)
           ^^^^^^^^^^^^^^^^^^^^^^^^^^^^^^^^^^^^^^^^^^^^^^^^^^^^^
  File "/opt/airflow/dags/cris.py", line 112, in generate_report
    pg_conn = pg_hook.get_conn()
              ^^^^^^^^^^^^^^^^^^
  File "/home/airflow/.local/lib/python3.12/site-packages/airflow/providers/postgres/hooks/postgres.py", line 161, in get_conn
    self.conn = psycopg2.connect(**conn_args)
                ^^^^^^^^^^^^^^^^^^^^^^^^^^^^^
  File "/home/airflow/.local/lib/python3.12/site-packages/psycopg2/__init__.py", line 122, in connect
    conn = _connect(dsn, connection_factory=connection_factory, **kwasync)
           ^^^^^^^^^^^^^^^^^^^^^^^^^^^^^^^^^^^^^^^^^^^^^^^^^^^^^^^^^^^^^^^
psycopg2.OperationalError: connection to server at "postgres" (172.18.0.3), port 5432 failed: FATAL:  database "weather_data" does not exist

[2024-05-18T13:06:35.892+0000] {taskinstance.py:1205} INFO - Marking task as UP_FOR_RETRY. dag_id=fetch_parse_store_report_weather_data, task_id=generate_report, execution_date=20240415T030000, start_date=20240518T130634, end_date=20240518T130635
[2024-05-18T13:06:35.958+0000] {standard_task_runner.py:110} ERROR - Failed to execute job 3227 for task generate_report (connection to server at "postgres" (172.18.0.3), port 5432 failed: FATAL:  database "weather_data" does not exist
; 590)
[2024-05-18T13:06:36.018+0000] {local_task_job_runner.py:240} INFO - Task exited with return code 1
[2024-05-18T13:06:36.063+0000] {taskinstance.py:3482} INFO - 0 downstream tasks scheduled from follow-on schedule check
[2024-05-18T13:06:36.065+0000] {local_task_job_runner.py:222} INFO - ::endgroup::
