[2024-05-25T11:26:56.597+0000] {local_task_job_runner.py:120} INFO - ::group::Pre task execution logs
[2024-05-25T11:26:56.633+0000] {taskinstance.py:2073} INFO - Dependencies all met for dep_context=non-requeueable deps ti=<TaskInstance: fetch_parse_store_report_forecast_weather_data.forecast_weather scheduled__2024-04-20T18:00:00+00:00 [queued]>
[2024-05-25T11:26:56.645+0000] {taskinstance.py:2073} INFO - Dependencies all met for dep_context=requeueable deps ti=<TaskInstance: fetch_parse_store_report_forecast_weather_data.forecast_weather scheduled__2024-04-20T18:00:00+00:00 [queued]>
[2024-05-25T11:26:56.646+0000] {taskinstance.py:2303} INFO - Starting attempt 2 of 2
[2024-05-25T11:26:56.668+0000] {taskinstance.py:2327} INFO - Executing <Task(PythonOperator): forecast_weather> on 2024-04-20 18:00:00+00:00
[2024-05-25T11:26:56.683+0000] {warnings.py:110} WARNING - /home/***/.local/lib/python3.12/site-packages/***/task/task_runner/standard_task_runner.py:61: DeprecationWarning: This process (pid=7855) is multi-threaded, use of fork() may lead to deadlocks in the child.
  pid = os.fork()

[2024-05-25T11:26:56.684+0000] {standard_task_runner.py:63} INFO - Started process 7914 to run task
[2024-05-25T11:26:56.685+0000] {standard_task_runner.py:90} INFO - Running: ['***', 'tasks', 'run', 'fetch_parse_store_report_forecast_weather_data', 'forecast_weather', 'scheduled__2024-04-20T18:00:00+00:00', '--job-id', '7254', '--raw', '--subdir', 'DAGS_FOLDER/cris.py', '--cfg-path', '/tmp/tmplbjy4bft']
[2024-05-25T11:26:56.686+0000] {standard_task_runner.py:91} INFO - Job 7254: Subtask forecast_weather
[2024-05-25T11:26:56.738+0000] {task_command.py:426} INFO - Running <TaskInstance: fetch_parse_store_report_forecast_weather_data.forecast_weather scheduled__2024-04-20T18:00:00+00:00 [running]> on host b151419bfa2a
[2024-05-25T11:26:56.832+0000] {taskinstance.py:2644} INFO - Exporting env vars: AIRFLOW_CTX_DAG_OWNER='***' AIRFLOW_CTX_DAG_ID='fetch_parse_store_report_forecast_weather_data' AIRFLOW_CTX_TASK_ID='forecast_weather' AIRFLOW_CTX_EXECUTION_DATE='2024-04-20T18:00:00+00:00' AIRFLOW_CTX_TRY_NUMBER='2' AIRFLOW_CTX_DAG_RUN_ID='scheduled__2024-04-20T18:00:00+00:00'
[2024-05-25T11:26:56.834+0000] {taskinstance.py:430} INFO - ::endgroup::
[2024-05-25T11:26:56.842+0000] {base.py:84} INFO - Using connection ID 'postgres_default' for task execution.
[2024-05-25T11:26:56.846+0000] {logging_mixin.py:188} INFO - Error connecting to the database or fetching data: connection to server at "postgres" (172.21.0.2), port 5432 failed: FATAL:  database "weather_data" does not exist
[2024-05-25T11:26:56.847+0000] {taskinstance.py:441} INFO - ::group::Post task execution logs
[2024-05-25T11:26:56.847+0000] {taskinstance.py:2890} ERROR - Task failed with exception
Traceback (most recent call last):
  File "/home/airflow/.local/lib/python3.12/site-packages/airflow/models/taskinstance.py", line 465, in _execute_task
    result = _execute_callable(context=context, **execute_callable_kwargs)
             ^^^^^^^^^^^^^^^^^^^^^^^^^^^^^^^^^^^^^^^^^^^^^^^^^^^^^^^^^^^^^
  File "/home/airflow/.local/lib/python3.12/site-packages/airflow/models/taskinstance.py", line 432, in _execute_callable
    return execute_callable(context=context, **execute_callable_kwargs)
           ^^^^^^^^^^^^^^^^^^^^^^^^^^^^^^^^^^^^^^^^^^^^^^^^^^^^^^^^^^^^
  File "/home/airflow/.local/lib/python3.12/site-packages/airflow/models/baseoperator.py", line 400, in wrapper
    return func(self, *args, **kwargs)
           ^^^^^^^^^^^^^^^^^^^^^^^^^^^
  File "/home/airflow/.local/lib/python3.12/site-packages/airflow/operators/python.py", line 235, in execute
    return_value = self.execute_callable()
                   ^^^^^^^^^^^^^^^^^^^^^^^
  File "/home/airflow/.local/lib/python3.12/site-packages/airflow/operators/python.py", line 252, in execute_callable
    return self.python_callable(*self.op_args, **self.op_kwargs)
           ^^^^^^^^^^^^^^^^^^^^^^^^^^^^^^^^^^^^^^^^^^^^^^^^^^^^^
  File "/opt/airflow/dags/cris.py", line 123, in forecast_weather
    pg_conn.close()
    ^^^^^^^
UnboundLocalError: cannot access local variable 'pg_conn' where it is not associated with a value
[2024-05-25T11:26:56.859+0000] {taskinstance.py:1205} INFO - Marking task as FAILED. dag_id=fetch_parse_store_report_forecast_weather_data, task_id=forecast_weather, execution_date=20240420T180000, start_date=20240525T112656, end_date=20240525T112656
[2024-05-25T11:26:56.871+0000] {standard_task_runner.py:110} ERROR - Failed to execute job 7254 for task forecast_weather (cannot access local variable 'pg_conn' where it is not associated with a value; 7914)
[2024-05-25T11:26:56.898+0000] {local_task_job_runner.py:240} INFO - Task exited with return code 1
[2024-05-25T11:26:56.924+0000] {taskinstance.py:3482} INFO - 0 downstream tasks scheduled from follow-on schedule check
[2024-05-25T11:26:56.929+0000] {local_task_job_runner.py:222} INFO - ::endgroup::
