[2024-05-25T10:11:39.343+0000] {local_task_job_runner.py:120} INFO - ::group::Pre task execution logs
[2024-05-25T10:11:39.398+0000] {taskinstance.py:2073} INFO - Dependencies all met for dep_context=non-requeueable deps ti=<TaskInstance: fetch_parse_store_report_forecast_weather_data.forecast_weather scheduled__2024-04-13T05:00:00+00:00 [queued]>
[2024-05-25T10:11:39.420+0000] {taskinstance.py:2073} INFO - Dependencies all met for dep_context=requeueable deps ti=<TaskInstance: fetch_parse_store_report_forecast_weather_data.forecast_weather scheduled__2024-04-13T05:00:00+00:00 [queued]>
[2024-05-25T10:11:39.421+0000] {taskinstance.py:2303} INFO - Starting attempt 1 of 2
[2024-05-25T10:11:39.468+0000] {taskinstance.py:2327} INFO - Executing <Task(PythonOperator): forecast_weather> on 2024-04-13 05:00:00+00:00
[2024-05-25T10:11:39.491+0000] {warnings.py:110} WARNING - /home/***/.local/lib/python3.12/site-packages/***/task/task_runner/standard_task_runner.py:61: DeprecationWarning: This process (pid=3207) is multi-threaded, use of fork() may lead to deadlocks in the child.
  pid = os.fork()

[2024-05-25T10:11:39.498+0000] {standard_task_runner.py:63} INFO - Started process 3334 to run task
[2024-05-25T10:11:39.501+0000] {standard_task_runner.py:90} INFO - Running: ['***', 'tasks', 'run', 'fetch_parse_store_report_forecast_weather_data', 'forecast_weather', 'scheduled__2024-04-13T05:00:00+00:00', '--job-id', '6497', '--raw', '--subdir', 'DAGS_FOLDER/cris.py', '--cfg-path', '/tmp/tmpmetxhjs9']
[2024-05-25T10:11:39.509+0000] {standard_task_runner.py:91} INFO - Job 6497: Subtask forecast_weather
[2024-05-25T10:11:39.664+0000] {task_command.py:426} INFO - Running <TaskInstance: fetch_parse_store_report_forecast_weather_data.forecast_weather scheduled__2024-04-13T05:00:00+00:00 [running]> on host 9dd3157499a4
[2024-05-25T10:11:39.906+0000] {taskinstance.py:2644} INFO - Exporting env vars: AIRFLOW_CTX_DAG_OWNER='***' AIRFLOW_CTX_DAG_ID='fetch_parse_store_report_forecast_weather_data' AIRFLOW_CTX_TASK_ID='forecast_weather' AIRFLOW_CTX_EXECUTION_DATE='2024-04-13T05:00:00+00:00' AIRFLOW_CTX_TRY_NUMBER='1' AIRFLOW_CTX_DAG_RUN_ID='scheduled__2024-04-13T05:00:00+00:00'
[2024-05-25T10:11:39.912+0000] {taskinstance.py:430} INFO - ::endgroup::
[2024-05-25T10:11:39.941+0000] {base.py:84} INFO - Using connection ID 'postgres_default' for task execution.
[2024-05-25T10:11:39.948+0000] {logging_mixin.py:188} INFO - Error connecting to the database or fetching data: connection to server at "postgres" (172.18.0.3), port 5432 failed: FATAL:  database "weather_data" does not exist
[2024-05-25T10:11:39.949+0000] {taskinstance.py:441} INFO - ::group::Post task execution logs
[2024-05-25T10:11:39.951+0000] {taskinstance.py:2890} ERROR - Task failed with exception
Traceback (most recent call last):
  File "/home/airflow/.local/lib/python3.12/site-packages/airflow/models/taskinstance.py", line 465, in _execute_task
    result = _execute_callable(context=context, **execute_callable_kwargs)
             ^^^^^^^^^^^^^^^^^^^^^^^^^^^^^^^^^^^^^^^^^^^^^^^^^^^^^^^^^^^^^
  File "/home/airflow/.local/lib/python3.12/site-packages/airflow/models/taskinstance.py", line 432, in _execute_callable
    return execute_callable(context=context, **execute_callable_kwargs)
           ^^^^^^^^^^^^^^^^^^^^^^^^^^^^^^^^^^^^^^^^^^^^^^^^^^^^^^^^^^^^
  File "/home/airflow/.local/lib/python3.12/site-packages/airflow/models/baseoperator.py", line 400, in wrapper
    return func(self, *args, **kwargs)
           ^^^^^^^^^^^^^^^^^^^^^^^^^^^
  File "/home/airflow/.local/lib/python3.12/site-packages/airflow/operators/python.py", line 235, in execute
    return_value = self.execute_callable()
                   ^^^^^^^^^^^^^^^^^^^^^^^
  File "/home/airflow/.local/lib/python3.12/site-packages/airflow/operators/python.py", line 252, in execute_callable
    return self.python_callable(*self.op_args, **self.op_kwargs)
           ^^^^^^^^^^^^^^^^^^^^^^^^^^^^^^^^^^^^^^^^^^^^^^^^^^^^^
  File "/opt/airflow/dags/cris.py", line 123, in forecast_weather
    pg_conn.close()
    ^^^^^^^
UnboundLocalError: cannot access local variable 'pg_conn' where it is not associated with a value
[2024-05-25T10:11:39.993+0000] {taskinstance.py:1205} INFO - Marking task as UP_FOR_RETRY. dag_id=fetch_parse_store_report_forecast_weather_data, task_id=forecast_weather, execution_date=20240413T050000, start_date=20240525T101139, end_date=20240525T101139
[2024-05-25T10:11:40.049+0000] {standard_task_runner.py:110} ERROR - Failed to execute job 6497 for task forecast_weather (cannot access local variable 'pg_conn' where it is not associated with a value; 3334)
[2024-05-25T10:11:40.134+0000] {local_task_job_runner.py:240} INFO - Task exited with return code 1
[2024-05-25T10:11:40.178+0000] {taskinstance.py:3482} INFO - 0 downstream tasks scheduled from follow-on schedule check
[2024-05-25T10:11:40.192+0000] {local_task_job_runner.py:222} INFO - ::endgroup::
