[2024-05-18T13:28:27.674+0000] {local_task_job_runner.py:120} INFO - ::group::Pre task execution logs
[2024-05-18T13:28:27.704+0000] {taskinstance.py:2073} INFO - Dependencies all met for dep_context=non-requeueable deps ti=<TaskInstance: fetch_parse_store_report_weather_data.generate_report scheduled__2024-04-17T04:00:00+00:00 [queued]>
[2024-05-18T13:28:27.714+0000] {taskinstance.py:2073} INFO - Dependencies all met for dep_context=requeueable deps ti=<TaskInstance: fetch_parse_store_report_weather_data.generate_report scheduled__2024-04-17T04:00:00+00:00 [queued]>
[2024-05-18T13:28:27.715+0000] {taskinstance.py:2303} INFO - Starting attempt 2 of 2
[2024-05-18T13:28:27.731+0000] {taskinstance.py:2327} INFO - Executing <Task(PythonOperator): generate_report> on 2024-04-17 04:00:00+00:00
[2024-05-18T13:28:27.742+0000] {warnings.py:110} WARNING - /home/***/.local/lib/python3.12/site-packages/***/task/task_runner/standard_task_runner.py:61: DeprecationWarning: This process (pid=1557) is multi-threaded, use of fork() may lead to deadlocks in the child.
  pid = os.fork()

[2024-05-18T13:28:27.744+0000] {standard_task_runner.py:63} INFO - Started process 1567 to run task
[2024-05-18T13:28:27.744+0000] {standard_task_runner.py:90} INFO - Running: ['***', 'tasks', 'run', 'fetch_parse_store_report_weather_data', 'generate_report', 'scheduled__2024-04-17T04:00:00+00:00', '--job-id', '3464', '--raw', '--subdir', 'DAGS_FOLDER/cris.py', '--cfg-path', '/tmp/tmpjxo7zzj1']
[2024-05-18T13:28:27.745+0000] {standard_task_runner.py:91} INFO - Job 3464: Subtask generate_report
[2024-05-18T13:28:27.799+0000] {task_command.py:426} INFO - Running <TaskInstance: fetch_parse_store_report_weather_data.generate_report scheduled__2024-04-17T04:00:00+00:00 [running]> on host d2eb9883ca8d
[2024-05-18T13:28:28.338+0000] {taskinstance.py:2644} INFO - Exporting env vars: AIRFLOW_CTX_DAG_OWNER='***' AIRFLOW_CTX_DAG_ID='fetch_parse_store_report_weather_data' AIRFLOW_CTX_TASK_ID='generate_report' AIRFLOW_CTX_EXECUTION_DATE='2024-04-17T04:00:00+00:00' AIRFLOW_CTX_TRY_NUMBER='2' AIRFLOW_CTX_DAG_RUN_ID='scheduled__2024-04-17T04:00:00+00:00'
[2024-05-18T13:28:28.340+0000] {taskinstance.py:430} INFO - ::endgroup::
[2024-05-18T13:28:28.354+0000] {base.py:84} INFO - Using connection ID 'postgres_default' for task execution.
[2024-05-18T13:28:28.359+0000] {taskinstance.py:441} INFO - ::group::Post task execution logs
[2024-05-18T13:28:28.360+0000] {taskinstance.py:2890} ERROR - Task failed with exception
Traceback (most recent call last):
  File "/home/airflow/.local/lib/python3.12/site-packages/airflow/models/taskinstance.py", line 465, in _execute_task
    result = _execute_callable(context=context, **execute_callable_kwargs)
             ^^^^^^^^^^^^^^^^^^^^^^^^^^^^^^^^^^^^^^^^^^^^^^^^^^^^^^^^^^^^^
  File "/home/airflow/.local/lib/python3.12/site-packages/airflow/models/taskinstance.py", line 432, in _execute_callable
    return execute_callable(context=context, **execute_callable_kwargs)
           ^^^^^^^^^^^^^^^^^^^^^^^^^^^^^^^^^^^^^^^^^^^^^^^^^^^^^^^^^^^^
  File "/home/airflow/.local/lib/python3.12/site-packages/airflow/models/baseoperator.py", line 400, in wrapper
    return func(self, *args, **kwargs)
           ^^^^^^^^^^^^^^^^^^^^^^^^^^^
  File "/home/airflow/.local/lib/python3.12/site-packages/airflow/operators/python.py", line 235, in execute
    return_value = self.execute_callable()
                   ^^^^^^^^^^^^^^^^^^^^^^^
  File "/home/airflow/.local/lib/python3.12/site-packages/airflow/operators/python.py", line 252, in execute_callable
    return self.python_callable(*self.op_args, **self.op_kwargs)
           ^^^^^^^^^^^^^^^^^^^^^^^^^^^^^^^^^^^^^^^^^^^^^^^^^^^^^
  File "/opt/airflow/dags/cris.py", line 112, in generate_report
    pg_conn = pg_hook.get_conn()
              ^^^^^^^^^^^^^^^^^^
  File "/home/airflow/.local/lib/python3.12/site-packages/airflow/providers/postgres/hooks/postgres.py", line 161, in get_conn
    self.conn = psycopg2.connect(**conn_args)
                ^^^^^^^^^^^^^^^^^^^^^^^^^^^^^
  File "/home/airflow/.local/lib/python3.12/site-packages/psycopg2/__init__.py", line 122, in connect
    conn = _connect(dsn, connection_factory=connection_factory, **kwasync)
           ^^^^^^^^^^^^^^^^^^^^^^^^^^^^^^^^^^^^^^^^^^^^^^^^^^^^^^^^^^^^^^^
psycopg2.OperationalError: connection to server at "postgres" (172.18.0.3), port 5432 failed: FATAL:  database "weather_data" does not exist

[2024-05-18T13:28:28.382+0000] {taskinstance.py:1205} INFO - Marking task as FAILED. dag_id=fetch_parse_store_report_weather_data, task_id=generate_report, execution_date=20240417T040000, start_date=20240518T132827, end_date=20240518T132828
[2024-05-18T13:28:28.403+0000] {standard_task_runner.py:110} ERROR - Failed to execute job 3464 for task generate_report (connection to server at "postgres" (172.18.0.3), port 5432 failed: FATAL:  database "weather_data" does not exist
; 1567)
[2024-05-18T13:28:28.446+0000] {local_task_job_runner.py:240} INFO - Task exited with return code 1
[2024-05-18T13:28:28.524+0000] {taskinstance.py:3482} INFO - 0 downstream tasks scheduled from follow-on schedule check
[2024-05-18T13:28:28.536+0000] {local_task_job_runner.py:222} INFO - ::endgroup::
