[2024-05-19T13:29:47.208+0000] {local_task_job_runner.py:120} INFO - ::group::Pre task execution logs
[2024-05-19T13:29:47.253+0000] {taskinstance.py:2073} INFO - Dependencies all met for dep_context=non-requeueable deps ti=<TaskInstance: fetch_parse_store_report_weather_data.check_files_exist scheduled__2024-05-08T14:00:00+00:00 [queued]>
[2024-05-19T13:29:47.271+0000] {taskinstance.py:2073} INFO - Dependencies all met for dep_context=requeueable deps ti=<TaskInstance: fetch_parse_store_report_weather_data.check_files_exist scheduled__2024-05-08T14:00:00+00:00 [queued]>
[2024-05-19T13:29:47.272+0000] {taskinstance.py:2303} INFO - Starting attempt 2 of 2
[2024-05-19T13:29:47.347+0000] {taskinstance.py:2327} INFO - Executing <Task(PythonOperator): check_files_exist> on 2024-05-08 14:00:00+00:00
[2024-05-19T13:29:47.361+0000] {warnings.py:110} WARNING - /home/***/.local/lib/python3.12/site-packages/***/task/task_runner/standard_task_runner.py:61: DeprecationWarning: This process (pid=3320) is multi-threaded, use of fork() may lead to deadlocks in the child.
  pid = os.fork()

[2024-05-19T13:29:47.367+0000] {standard_task_runner.py:63} INFO - Started process 3348 to run task
[2024-05-19T13:29:47.367+0000] {standard_task_runner.py:90} INFO - Running: ['***', 'tasks', 'run', 'fetch_parse_store_report_weather_data', 'check_files_exist', 'scheduled__2024-05-08T14:00:00+00:00', '--job-id', '6055', '--raw', '--subdir', 'DAGS_FOLDER/cris.py', '--cfg-path', '/tmp/tmpb6ohudco']
[2024-05-19T13:29:47.370+0000] {standard_task_runner.py:91} INFO - Job 6055: Subtask check_files_exist
[2024-05-19T13:29:47.471+0000] {task_command.py:426} INFO - Running <TaskInstance: fetch_parse_store_report_weather_data.check_files_exist scheduled__2024-05-08T14:00:00+00:00 [running]> on host d2eb9883ca8d
[2024-05-19T13:29:48.004+0000] {taskinstance.py:2644} INFO - Exporting env vars: AIRFLOW_CTX_DAG_OWNER='***' AIRFLOW_CTX_DAG_ID='fetch_parse_store_report_weather_data' AIRFLOW_CTX_TASK_ID='check_files_exist' AIRFLOW_CTX_EXECUTION_DATE='2024-05-08T14:00:00+00:00' AIRFLOW_CTX_TRY_NUMBER='2' AIRFLOW_CTX_DAG_RUN_ID='scheduled__2024-05-08T14:00:00+00:00'
[2024-05-19T13:29:48.006+0000] {taskinstance.py:430} INFO - ::endgroup::
[2024-05-19T13:29:48.008+0000] {taskinstance.py:441} INFO - ::group::Post task execution logs
[2024-05-19T13:29:48.009+0000] {taskinstance.py:2890} ERROR - Task failed with exception
Traceback (most recent call last):
  File "/home/airflow/.local/lib/python3.12/site-packages/airflow/models/taskinstance.py", line 465, in _execute_task
    result = _execute_callable(context=context, **execute_callable_kwargs)
             ^^^^^^^^^^^^^^^^^^^^^^^^^^^^^^^^^^^^^^^^^^^^^^^^^^^^^^^^^^^^^
  File "/home/airflow/.local/lib/python3.12/site-packages/airflow/models/taskinstance.py", line 432, in _execute_callable
    return execute_callable(context=context, **execute_callable_kwargs)
           ^^^^^^^^^^^^^^^^^^^^^^^^^^^^^^^^^^^^^^^^^^^^^^^^^^^^^^^^^^^^
  File "/home/airflow/.local/lib/python3.12/site-packages/airflow/models/baseoperator.py", line 400, in wrapper
    return func(self, *args, **kwargs)
           ^^^^^^^^^^^^^^^^^^^^^^^^^^^
  File "/home/airflow/.local/lib/python3.12/site-packages/airflow/operators/python.py", line 235, in execute
    return_value = self.execute_callable()
                   ^^^^^^^^^^^^^^^^^^^^^^^
  File "/home/airflow/.local/lib/python3.12/site-packages/airflow/operators/python.py", line 252, in execute_callable
    return self.python_callable(*self.op_args, **self.op_kwargs)
           ^^^^^^^^^^^^^^^^^^^^^^^^^^^^^^^^^^^^^^^^^^^^^^^^^^^^^
  File "/opt/airflow/dags/cris.py", line 166, in check_files_exist
    raise FileNotFoundError(f"File {file} does not exist")
FileNotFoundError: File /tmp/report.txt does not exist
[2024-05-19T13:29:48.033+0000] {taskinstance.py:1205} INFO - Marking task as FAILED. dag_id=fetch_parse_store_report_weather_data, task_id=check_files_exist, execution_date=20240508T140000, start_date=20240519T132947, end_date=20240519T132948
[2024-05-19T13:29:48.072+0000] {standard_task_runner.py:110} ERROR - Failed to execute job 6055 for task check_files_exist (File /tmp/report.txt does not exist; 3348)
[2024-05-19T13:29:48.123+0000] {local_task_job_runner.py:240} INFO - Task exited with return code 1
[2024-05-19T13:29:48.171+0000] {taskinstance.py:3482} INFO - 0 downstream tasks scheduled from follow-on schedule check
[2024-05-19T13:29:48.179+0000] {local_task_job_runner.py:222} INFO - ::endgroup::
